Workbook

Sheet RL Data
B2: Metric Explanation | C2: BPM | D2: =VLOOKUP(C2,'Data Dictionary'!B:C,2,FALSE) -> Boost used per minute
B5: Player | C5: Team | D5: Games Played | E5: BCPM Value | F5: BCPM Percentile | G5: BPM | H5: BPM Percentile | I5: Small Pad Count Per Game | J5: Big Pad Count Per Game | K5: Time At 0% Boost Per Game | L5: % Behind Ball | M5: Avg. Distance Between Teammates | N5: Shots Per Game | O5: Saves Per Game | P5: Goals Conceded Per Game | Q5: Goals Per Game | R5: Shot Success | S5: Defense Success | T5: Time at 0 Boost Total
B6: Bear | C6: AEY | D6: 6 | E6: 360.22 | F6: 0.166 | G6: 359.69 | H6: 0.333 | I6: 63.17 | J6: 22.83 | K6: 30.41 | L6: 0.6772 | M6: 3435.87 | N6: 2.83 | O6: 1.83 | P6: 2.33 | Q6: 1 | R6: 0.3529 | S6: 0.25 | T6: =K6*D6 -> 182.46
B7: CaveManRL | C7: CLRTY | D7: 2 | E7: 384.49 | F7: 0.666 | G7: 386.36 | H7: 0.666 | I7: 71.5 | J7: 24.5 | K7: 51.31 | L7: 0.7664 | M7: 3810.23 | N7: 2 | O7: 1.5 | P7: 2 | Q7: 0 | R7: 0 | S7: 0.25 | T7: =K7*D7 -> 102.62
B8: Hexxuy | C8: CLRTY | D8: 6 | E8: 390.7 | F8: 0.833 | G8: 408.37 | H8: 0.833 | I8: 83.83 | J8: 19.83 | K8: 38.01 | L8: 0.7481 | M8: 3803.03 | N8: 3.5 | O8: 1.83 | P8: 2 | Q8: 1.33 | R8: 0.381 | S8: 0.42 | T8: =K8*D8 -> 228.06
B9: Iknokz2782 | C9: CLRTY | D9: 6 | E9: 353.21 | F9: 0 | G9: 358.38 | H9: 0.166 | I9: 62.17 | J9: 21.5 | K9: 33.42 | L9: 0.826 | M9: 3866.82 | N9: 2.17 | O9: 2.17 | P9: 2 | Q9: 0.67 | R9: 0.3077 | S9: 0.58 | T9: =K9*D9 -> 200.52
B10: Peas and Beans | C10: AEY | D10: 6 | E10: 368.38 | F10: 0.5 | G10: 362.21 | H10: 0.5 | I10: 81 | J10: 19.83 | K10: 38.32 | L10: 0.6966 | M10: 3541.91 | N10: 2.5 | O10: 1.17 | P10: 2.33 | Q10: 0.5 | R10: 0.2 | S10: -0.08 | T10: =K10*D10 -> 229.92
B11: sly | C11: AEY | D11: 6 | E11: 361.81 | F11: 0.333 | G11: 351.75 | H11: 0 | I11: 52 | J11: 22.17 | K11: 44.38 | L11: 0.7241 | M11: 3581.71 | N11: 3.17 | O11: 2.17 | P11: 2.33 | Q11: 0.5 | R11: 0.1579 | S11: 0.42 | T11: =K11*D11 -> 266.28
B12: t. | C12: CLRTY | D12: 4 | E12: 434.63 | F12: 1 | G12: 435.54 | H12: 1 | I12: 55.5 | J12: 23.25 | K12: 61.2 | L12: 0.7554 | M12: 4047.22 | N12: 2.5 | O12: 1.5 | P12: 2 | Q12: 0.5 | R12: 0.2 | S12: 0.25 | T12: =K12*D12 -> 244.8
B13: Atomic | C13: Team Envy | D13: 7 | E13: 431 | F13: 1 | G13: 430.58 | H13: 0.8 | I13: 64.29 | J13: 21 | K13: 60.41 | L13: 0.7383 | M13: 3707.51 | N13: 1.71 | O13: 1.43 | P13: 1.29 | Q13: 0.29 | R13: 0.1667 | S13: 0.57 | T13: =K13*D13 -> 422.87
B14: GarrettG | C14: NRG | D14: 7 | E14: 395.74 | F14: 0.2 | G14: 409.01 | H14: 0.2 | I14: 66.14 | J14: 19.71 | K14: 33.35 | L14: 0.7183 | M14: 3673.71 | N14: 2.14 | O14: 1.57 | P14: 1.43 | Q14: 0 | R14: 0 | S14: 0.57 | T14: =K14*D14 -> 233.45
B15: NRG jstn. widepeeposad | C15: NRG | D15: 7 | E15: 426.95 | F15: 0.8 | G15: 437.71 | H15: 1 | I15: 60.43 | J15: 22 | K15: 35.14 | L15: 0.7346 | M15: 3652.75 | N15: 3 | O15: 1.43 | P15: 1.43 | Q15: 0.57 | R15: 0.1905 | S15: 0.5 | T15: =K15*D15 -> 245.98
B16: Squishy | C16: NRG | D16: 7 | E16: 405.58 | F16: 0.4 | G16: 417.78 | H16: 0.6 | I16: 58.43 | J16: 20.86 | K16: 48.26 | L16: 0.7362 | M16: 3699.43 | N16: 2.14 | O16: 1.29 | P16: 1.43 | Q16: 0.71 | R16: 0.3333 | S16: 0.43 | T16: =K16*D16 -> 337.82
B17: Turbopolsa | C17: Team Envy | D17: 7 | E17: 355.38 | F17: 0 | G17: 351.91 | H17: 0 | I17: 60.14 | J17: 18.43 | K17: 20.02 | L17: 0.7099 | M17: 3825.82 | N17: 3 | O17: 1.43 | P17: 1.29 | Q17: 0.71 | R17: 0.2381 | S17: 0.57 | T17: =K17*D17 -> 140.14
B18: mist | C18: Team Envy | D18: 7 | E18: 408.24 | F18: 0.6 | G18: 417.7 | H18: 0.4 | I18: 53.71 | J18: 21.86 | K18: 50.67 | L18: 0.7568 | M18: 3777.93 | N18: 2.71 | O18: 1.29 | P18: 1.29 | Q18: 0.43 | R18: 0.1579 | S18: 0.5 | T18: =K18*D18 -> 354.69
C22: Team | D22: Games Played | E22: BCPM Value | F22: BCPM Percentile | G22: BPM | H22: BPM Percentile | I22: Small Pad Count Per Game | J22: Big Pad Count Per Game | K22: Time At 0% Boost Per Game | L22: % Behind Ball | M22: Avg. Distance Between Teammates | N22: Shots Per Game | O22: Saves Per Game | P22: Goals Conceded Per Game | Q22: Goals Per Game | R22: Shot Success | S22: Defense Success
C23: AEY | D23: 6 | E23: 1090.41 | F23: 0.999 | G23: 1073.65 | H23: 0.833 | I23: 196.16667 | J23: 64.833333 | K23: 113.11 | L23: 2.0979 | M23: 10559.49 | N23: 8.5 | O23: 5.1666667 | P23: 7 | Q23: 2 | R23: 0.71083591 | S23: 0.58333333
C24: CLRTY | D24: 6 | E24: 1563.03 | F24: 2.499 | G24: 1588.65 | H24: 2.665 | I24: 273 | J24: 89.083333 | K24: 183.92167 | L24: 3.0959 | M24: 15527.3 | N24: 10.166667 | O24: 7 | P24: 8 | Q24: 2.5 | R24: 0.88864469 | S24: 1.5
C25: AEY Difference | E25: -472.62 | F25: -1.5 | G25: -515 | H25: -1.832 | I25: -76.833333 | J25: -24.25 | K25: -70.811667 | L25: -0.998 | M25: -4967.81 | N25: -1.6666667 | O25: -1.8333333 | P25: -1 | Q25: -0.5 | R25: -0.17780878 | S25: -0.91666667
C30: Team Insights
C31: Boost economy gap is massive, the difference in AEY vs CLRTY BCPM, BPM, Small Pads/Game and Big Pads/Game outlines inefficiency
C32: AEY defended much more than attacking when analyzing Shots/Game, Saves/Game, and Goals Conceded/Game. CLRTY Shot and Saved more. Notes: CLRTY played faster, took more risks, and traded goals at a positive rate, AEY didn't trade, they absorbed
C33: Time at 0 Boost gap was too big, CLRTY having a lower 0 boost time with a higher BPM and BCPM shows that their time at 0 boost was intentional risks, AEYs 0 boost moments were forced.
C34: CLRTY % behind ball and distance from teammates compared to AEY proves that CLRTY spread wider, rotates faster, and and leaves structure to pressure. This also points to possible lack of midfield pressure by AEY, especially when taking low pad count and low BCPM into consideration
C35: Shot success and defensive succes show that CLRTY converts pressure and defends proactively, AEY converts okay but defends reactively
C38: Player insights
C39: Bear | D39: BCPM: 16.6th percentile ? poor boost collection BPM: 33.3rd percentile ? not compensating with speed Shots/game: 2.83 ? modest pressure Goals conceded/game: 2.33 Shot success: 35.3% (fine, but volume is low) | H39: Bear plays safe and efficient individually, but: Doesn’t collect enough boost to sustain pressure Doesn’t shoot enough to flip momentum Ends up defending more than attacking | K39: Why this matters vs CLRTY: Against a high-BCPM team, “safe but slow” becomes permanent defense.
C40: Peas And Beans | D40: BCPM: 50th percentile (average) Shots/game: 2.5 Goals/game: 0.5 Defense success: ?0.08 (negative impact) | H40: This is a classic passive support role: Doesn’t lose games mechanically Doesn’t win games either Fails to punish CLRTY’s aggressive rotations | K40: Why this matters: When no one steps up as a pressure driver, the opponent controls midfield uncontested.
C41: Sly | D41: BPM: 0th percentile BCPM: 33rd percentile Time @ 0 boost: 44.4s/game Shots/game: 3.17 (highest on AEY) Shot success: 15.8% (very low) | H41: sly is: Trying to force offense Doing it without boost Shooting under pressure or from bad positions That combination is brutal: Missed shots ? long clears ? immediate counterattack | K41: Why this loses games: This creates free possessions for CLRTY, not pressure.
C44: Loss driven by lack of pressure roles: all AEY players below median BCPM and none above 3.2 shots/game with positive efficiency. Opponent maintained tempo through superior boost control and role diversity.
C48: AEY Verse NRG
C49: Boost collection, AEY at 360 avg where NRG is 405 avg is an ENORMOUS gap. Explains late challenges, fewer counter attacks, more rfeactive saves
C50: Shot efficiency verse shot quality; AEY shoots under pressure, lower success rate, fewer rebound opportunities. NRG shoots after boost denial, even when goals are low, shots create chaos.
C51: No defined pressure engine or balanced roles: NRG always has one player forcing plays, one ready for second touch, one stablizing behind. AEY has 3 players rotating safely which kills tempo
C54: Right now, all of AEY plays a stabalizer role. Based on data, Sly should drive tempo like GarrettG, Bear should be Pressure/Finisher like squishy, Peas and Beans should be stabalizer like NRG jstn. widepeeposad.
C57: GOALS
C59: Bear to increase BCPM from 360 to 390+
C60: Sly to increase BCPM from 362 to 390+
C61: Challenge at 40 - 60 boost, not at 20. This lowers time at 0 boost, saves needed, goals conceded. NRG IS NOT FASTER, THEY ARE EARLIER
C62: Force awkward saves, push to increase shots per game per player to 3+. Shoot to create pressure, not score.
...

Sheet Player Comparison
B3: Change Player Names Using Drop Down | K3: . | Y3: Change Team Names Using Drop Down | AE3: =IF(AC5=Z5,"Why you comparfe same team, make no sense, you change now.","")
B5: Player 1 | C5: GarrettG | F5: Player 2 | G5: Squishy | I5: =IF(G5=C5,"Why You Compare Same People, Make No Sense, Change Now","") | Y5: Team | Z5: AEY | AB5: Team | AC5: CLRTY | AE5: =IF(AND(OR(Z5="AEY",AC5="CLRTY",Z5="CLRTY",AC5="AEY"),OR(Z5="NRG",AC5="Team Envy",Z5="Team Envy",AC5="NRG"))=TRUE,"Keep in mind, Comparing AEY or CLRTY to NRG or Team Envy will result in skewed data since they didn't play each other.","")
Y54: ..

Sheet Data Dictionary
B2: Column | C2: Description
B3: Player | C3: Player username
B4: Team | C4: Team or color designation
B5: Games | C5: Number of games included
B6: Avg Speed | C6: Average movement speed
B7: % SlowSpeed | C7: Time spent below supersonic speed
B8: % BoostSpeed | C8: Time spent at boosted speed
B9: % SupersonicSpeed | C9: Time spent supersonic
B10: % Ground | C10: Time spent on the ground
B11: % Low Air | C11: Time spent airborne below crossbar
B12: % High Air | C12: Time spent airborne above crossbar
B13: Powerslidecount | C13: Total number of powerslides
... B60: BPM Percentile | C60: Boost used per minute Index with other player deviation

Sheet Player Compare Data
C2: ='Player Comparison'!C5 -> GarrettG | D2: ='Player Comparison'!G5 -> Squishy | V2: ='Player Comparison'!Z5 -> AEY | W2: ='Player Comparison'!AC5 -> CLRTY
Z5: AEY
B6: Player | C6: Small Pad Count Per Game | D6: Big Pad Count Per Game | U6: Player | V6: Small Pad Count Per Game | W6: Big Pad Count Per Game | Z6: CLRTY
B7: =$C$2 -> GarrettG | C7: =VLOOKUP($B7,'RL Data'!$B$5:$S$18,MATCH('Player Compare Data'!C$6,'RL Data'!$B$5:$S$5,0),FALSE) -> 66.14 | D7: =VLOOKUP($B7,'RL Data'!$B$5:$S$18,MATCH('Player Compare Data'!D$6,'RL Data'!$B$5:$S$5,0),FALSE) -> 19.71 | U7: =$V$2 -> AEY | V7: =SUMIFS('RL Data'!I6:I18,'RL Data'!C6:C18,'Player Compare Data'!U7) -> 196.17 | W7: =SUMIFS('RL Data'!J6:J18,'RL Data'!C6:C18,'Player Compare Data'!U7) -> 64.83 | Z7: Team Envy
B8: =$D$2 -> Squishy | C8: =VLOOKUP($B8,'RL Data'!$B$5:$S$18,MATCH('Player Compare Data'!C$6,'RL Data'!$B$5:$S$5,0),FALSE) -> 58.43 | D8: =VLOOKUP($B8,'RL Data'!$B$5:$S$18,MATCH('Player Compare Data'!D$6,'RL Data'!$B$5:$S$5,0),FALSE) -> 20.86 | U8: =$W$2 -> CLRTY | V8: =SUMIFS('RL Data'!I6:I18,'RL Data'!C6:C18,'Player Compare Data'!U8) -> 273 | W8: =SUMIFS('RL Data'!J6:J18,'RL Data'!C6:C18,'Player Compare Data'!U8) -> 89.08 | Z8: NRG
C9: =(C8-C7)/C7 -> -0.11657091 | D9: =(D8-D7)/D7 -> 0.058346017 | V9: =IFERROR((V8-V7)/V7,"One or more Values is 0") -> 0.3916501 | W9: =IFERROR((W8-W7)/W7,"One or more Values is 0") -> 0.37405522
C10: =IFERROR(IF(C9<0,CONCATENATE(B8," Collected ",TEXT(C9*-1,"0.00%")," Less Small Pads Compared To ",B7),CONCATENATE(B8," Collected ",TEXT(C9,"0.00%")," More Small Pads Compared To ",B7)),"One Or More Data Values is 0") -> Squishy Collected 11.66% Less Small Pads Compared To GarrettG | D10: =IFERROR(IF(D9<0,CONCATENATE(B8," Collected ",TEXT(D9*-1,"0.00%")," Less Big Pads Compared To ",B7),CONCATENATE(B8," Collected ",TEXT(D9,"0.00%")," More Big Pads Compared To ",B7)),"One Or More Data Values is 0") -> Squishy Collected 5.83% More Big Pads Compared To GarrettG | V10: =IFERROR(IF(V9<0,CONCATENATE(U8," Collected ",TEXT(V9*-1,"0.00%")," Less Small Pads Compared To ",U7),CONCATENATE(U8," Collected ",TEXT(V9,"0.00%")," More Small Pads Compared To ",U7)),"One Or More Data Values is 0") -> CLRTY Collected 39.17% More Small Pads Compared To AEY | W10: =IFERROR(IF(W9<0,CONCATENATE(U8," Collected ",TEXT(W9*-1,"0.00%")," Less Big Pads Compared To ",U7),CONCATENATE(U8," Collected ",TEXT(W9,"0.00%")," More Big Pads Compared To ",U7)),"One Or More Data Values is 0") -> CLRTY Collected 37.41% More Big Pads Compared To AEY
C12: BCPM Value | D12: BPM | V12: BCPM Value | W12: BPM
B13: =$C$2 -> GarrettG | C13: =VLOOKUP($B13,'RL Data'!$B$5:$S$18,MATCH('Player Compare Data'!C$12,'RL Data'!$B$5:$S$5,0),FALSE) -> 395.74 | D13: =VLOOKUP($B13,'RL Data'!$B$5:$S$18,MATCH('Player Compare Data'!D$12,'RL Data'!$B$5:$S$5,0),FALSE) -> 409.01 | U13: =$V$2 -> AEY | V13: =SUMIFS('RL Data'!E6:E18,'RL Data'!C6:C18,'Player Compare Data'!U13) -> 1090.41 | W13: =SUMIFS('RL Data'!G6:G18,'RL Data'!C6:C18,'Player Compare Data'!U13) -> 1073.65 | Y13: =AND(OR(Z13="AEY",Z14="CLRTY",Z13="CLRTY",Z14="AEY"),OR(Z13="NRG",Z14="Team Envy",Z13="Team Envy",Z14="NRG")) -> FALSE | Z13: Team Envy
B14: =$D$2 -> Squishy | C14: =VLOOKUP($B14,'RL Data'!$B$5:$S$18,MATCH('Player Compare Data'!C$12,'RL Data'!$B$5:$S$5,0),FALSE) -> 405.58 | D14: =VLOOKUP($B14,'RL Data'!$B$5:$S$18,MATCH('Player Compare Data'!D$12,'RL Data'!$B$5:$S$5,0),FALSE) -> 417.78 | U14: =$W$2 -> CLRTY | V14: =SUMIFS('RL Data'!E6:E18,'RL Data'!C6:C18,'Player Compare Data'!U14) -> 1563.03 | W14: =SUMIFS('RL Data'!G6:G18,'RL Data'!C6:C18,'Player Compare Data'!U14) -> 1588.65 | Z14: NRG
C15: =(C14-C13)/C13 -> 0.02486481 | D15: =(D14-D13)/D13 -> 0.021442019 | V15: =IFERROR((V14-V13)/V13,"One or more Values is 0") -> 0.4334333 | W15: =IFERROR((W14-W13)/W13,"One or more Values is 0") -> 0.47967215
C16: =IFERROR(IF(C15<0,CONCATENATE(B14," Collected ",TEXT(C15*-1,"0.00%")," Less Boost Compared To ",B13),CONCATENATE(B14," Collected ",TEXT(C15,"0.00%")," More Boost Compared To ",B13)),"One Or More Data Values is 0") -> Squishy Collected 2.49% More Boost Compared To GarrettG | D16: =IFERROR(IF(D15<0,CONCATENATE(B14," Used ",TEXT(D15*-1,"0.00%")," Less Boost Compared To ",B13),CONCATENATE(B14," Used ",TEXT(D15,"0.00%")," More Boost Compared To ",B13)),"One Or More Data Values is 0") -> Squishy Used 2.14% More Boost Compared To GarrettG | V16: =IFERROR(IF(V15<0,CONCATENATE(U14," Collected ",TEXT(V15*-1,"0.00%")," Less Boost Compared To ",U13),CONCATENATE(U14," Collected ",TEXT(V15,"0.00%")," More Boost Compared To ",U13)),"One Or More Data Values is 0") -> CLRTY Collected 43.34% More Boost Compared To AEY | W16: =IFERROR(IF(W15<0,CONCATENATE(U14," Used ",TEXT(W15*-1,"0.00%")," Less Boost Compared To ",U13),CONCATENATE(U14," Used ",TEXT(W15,"0.00%")," More Boost Compared To ",U13)),"One Or More Data Values is 0") -> CLRTY Used 47.97% More Boost Compared To AEY
C18: Shots Per Game | D18: Goals Per Game | V18: Shots Per Game | W18: Goals Per Game
B19: =$C$2 -> GarrettG | C19: =VLOOKUP($B19,'RL Data'!$B$5:$S$18,MATCH('Player Compare Data'!C$18,'RL Data'!$B$5:$S$5,0),FALSE) -> 2.14 | D19: =VLOOKUP($B19,'RL Data'!$B$5:$S$18,MATCH('Player Compare Data'!D$18,'RL Data'!$B$5:$S$5,0),FALSE) -> 0 | U19: =$V$2 -> AEY | V19: =SUMIFS('RL Data'!N6:N18,'RL Data'!C6:C18,'Player Compare Data'!U19) -> 8.5 | W19: =SUMIFS('RL Data'!Q6:Q18,'RL Data'!C6:C18,'Player Compare Data'!U19) -> 2
B20: =$D$2 -> Squishy | C20: =VLOOKUP($B20,'RL Data'!$B$5:$S$18,MATCH('Player Compare Data'!C$18,'RL Data'!$B$5:$S$5,0),FALSE) -> 2.14 | D20: =VLOOKUP($B20,'RL Data'!$B$5:$S$18,MATCH('Player Compare Data'!D$18,'RL Data'!$B$5:$S$5,0),FALSE) -> 0.71 | U20: =$W$2 -> CLRTY | V20: =SUMIFS('RL Data'!N6:N18,'RL Data'!C6:C18,'Player Compare Data'!U20) -> 10.17 | W20: =SUMIFS('RL Data'!Q6:Q18,'RL Data'!C6:C18,'Player Compare Data'!U20) -> 2.5
C21: =(C20-C19)/C19 -> 0 | D21: =(D20-D19)/D19 -> #DIV/0! | V21: =IFERROR((V20-V19)/V19,"One or more Values is 0") -> 0.19647059 | W21: =IFERROR((W20-W19)/W19,"One or more Values is 0") -> 0.25
C22: =IFERROR(IF(C21<0,CONCATENATE(B20," Had ",TEXT(C21*-1,"0.00%")," Less Shots Per Game Compared To ",B19),CONCATENATE(B20," Had ",TEXT(C21,"0.00%")," More Shots Per Game Compared To ",B19)),"One Or More Data Values is 0") -> Squishy Had 0.00% More Shots Per Game Compared To GarrettG | D22: =IFERROR(IF(D21<0,CONCATENATE(B20," Had ",TEXT(D21*-1,"0.00%")," Less Goals Per Game Compared To ",B19),CONCATENATE(B20," Had ",TEXT(D21,"0.00%")," More Goals Per Game Compared To ",B19)),"One Or More Data Values is 0") -> One Or More Data Values is 0 | V22: =IFERROR(IF(V21<0,CONCATENATE(U20," Had ",TEXT(V21*-1,"0.00%")," Less Shots Per Game Compared To ",U19),CONCATENATE(U20," Had ",TEXT(V21,"0.00%")," More Shots Per Game Compared To ",U19)),"One Or More Data Values is 0") -> CLRTY Had 19.65% More Shots Per Game Compared To AEY | W22: =IFERROR(IF(W21<0,CONCATENATE(U20," Had ",TEXT(W21*-1,"0.00%")," Less Goals Per Game Compared To ",U19),CONCATENATE(U20," Had ",TEXT(W21,"0.00%")," More Goals Per Game Compared To ",U19)),"One Or More Data Values is 0") -> CLRTY Had 25.00% More Goals Per Game Compared To AEY
C24: Saves Per Game | D24: Goals Conceded Per Game | V24: Saves Per Game | W24: Goals Conceded Per Game
B25: =$C$2 -> GarrettG | C25: =VLOOKUP($B25,'RL Data'!$B$5:$S$18,MATCH('Player Compare Data'!C$24,'RL Data'!$B$5:$S$5,0),FALSE) -> 1.57 | D25: =VLOOKUP($B25,'RL Data'!$B$5:$S$18,MATCH('Player Compare Data'!D$24,'RL Data'!$B$5:$S$5,0),FALSE) -> 1.43 | U25: =$V$2 -> AEY | V25: =SUMIFS('RL Data'!O6:O18,'RL Data'!C6:C18,'Player Compare Data'!U25) -> 5.17 | W25: =SUMIFS('RL Data'!P6:P18,'RL Data'!C6:C18,'Player Compare Data'!U25) -> 6.99
B26: =$D$2 -> Squishy | C26: =VLOOKUP($B26,'RL Data'!$B$5:$S$18,MATCH('Player Compare Data'!C$24,'RL Data'!$B$5:$S$5,0),FALSE) -> 1.29 | D26: =VLOOKUP($B26,'RL Data'!$B$5:$S$18,MATCH('Player Compare Data'!D$24,'RL Data'!$B$5:$S$5,0),FALSE) -> 1.43 | U26: =$W$2 -> CLRTY | V26: =SUMIFS('RL Data'!O6:O18,'RL Data'!C6:C18,'Player Compare Data'!U26) -> 7 | W26: =SUMIFS('RL Data'!P6:P18,'RL Data'!C6:C18,'Player Compare Data'!U26) -> 8
C27: =(C26-C25)/C25 -> -0.17834395 | D27: =(D26-D25)/D25 -> 0 | V27: =IFERROR((V26-V25)/V25,"One or more Values is 0") -> 0.35396518 | W27: =IFERROR((W26-W25)/W25,"One or more Values is 0") -> 0.14449213
C28: =IFERROR(IF(C27<0,CONCATENATE(B26," Had ",TEXT(C27*-1,"0.00%")," Less Saves Compared To ",B25),CONCATENATE(B26," Had ",TEXT(C27,"0.00%")," More Saves Compared To ",B25)),"One Or More Data Values is 0") -> Squishy Had 17.83% Less Saves Compared To GarrettG | D28: =IFERROR(IF(D27<0,CONCATENATE(B26," Had ",TEXT(D27*-1,"0.00%")," Less Goals Conceded Compared To ",B25),CONCATENATE(B26," Had ",TEXT(D27,"0.00%")," More Goals Conceded Compared To ",B25)),"One Or More Data Values is 0") -> Squishy Had 0.00% More Goals Conceded Compared To GarrettG | V28: =IFERROR(IF(V27<0,CONCATENATE(U26," Had ",TEXT(V27*-1,"0.00%")," Less Saves Compared To ",U25),CONCATENATE(U26," Had ",TEXT(V27,"0.00%")," More Saves Compared To ",U25)),"One Or More Data Values is 0") -> CLRTY Had 35.40% More Saves Compared To AEY | W28: =IFERROR(IF(W27<0,CONCATENATE(U26," Had ",TEXT(W27*-1,"0.00%")," Less Goals Conceded Compared To ",U25),CONCATENATE(U26," Had ",TEXT(W27,"0.00%")," More Goals Conceded Compared To ",U25)),"One Or More Data Values is 0") -> CLRTY Had 14.45% More Goals Conceded Compared To AEY
C30: Time At 0% Boost Per Game | V30: Time At 0% Boost Per Game
B31: =$C$2 -> GarrettG | C31: =VLOOKUP($B31,'RL Data'!$B$5:$S$18,MATCH('Player Compare Data'!C$30,'RL Data'!$B$5:$S$5,0),FALSE) -> 33.35 | U31: =$V$2 -> AEY | V31: =AVERAGEIFS('RL Data'!K6:K18,'RL Data'!C6:C18,'Player Compare Data'!U31) -> 37.703333
B32: =$D$2 -> Squishy | C32: =VLOOKUP($B32,'RL Data'!$B$5:$S$18,MATCH('Player Compare Data'!C$30,'RL Data'!$B$5:$S$5,0),FALSE) -> 48.26 | U32: =$W$2 -> CLRTY | V32: =AVERAGEIFS('RL Data'!K6:K18,'RL Data'!C6:C18,'Player Compare Data'!U32) -> 45.985
C33: =(C32-C31)/C31 -> 0.44707646 | V33: =IFERROR((V32-V31)/V31,"One or more Values is 0") -> 0.21965343
C34: =IFERROR(IF(C33<0,CONCATENATE(B32," Had ",TEXT(C33*-1,"0.00%")," Less Time at 0 Boost Compared To ",B31),CONCATENATE(B32," Had ",TEXT(C33,"0.00%")," More Time at 0 Boost Compared To ",B31)),"One Or More Data Values is 0") -> Squishy Had 44.71% More Time at 0 Boost Compared To GarrettG | V34: =IFERROR(IF(V33<0,CONCATENATE(U32," Had ",TEXT(V33*-1,"0.00%")," Less Avg. Time at 0 Boost Compared To ",U31),CONCATENATE(U32," Had ",TEXT(V33,"0.00%")," More Avg. Time at 0 Boost Compared To ",U31)),"One Or More Data Values is 0") -> CLRTY Had 21.97% More Avg. Time at 0 Boost Compared To AEY
C36: Avg. Distance Between Teammates | V36: Avg. Distance Between Teammates
B37: =$C$2 -> GarrettG | C37: =VLOOKUP($B37,'RL Data'!$B$5:$S$18,MATCH('Player Compare Data'!C$36,'RL Data'!$B$5:$S$5,0),FALSE) -> 3673.71 | U37: =$V$2 -> AEY | V37: =SUMIFS('RL Data'!M6:M18,'RL Data'!C6:C18,'Player Compare Data'!U37)/COUNTIF('RL Data'!C6:C18,'Player Compare Data'!U37) -> 3519.83
B38: =$D$2 -> Squishy | C38: =VLOOKUP($B38,'RL Data'!$B$5:$S$18,MATCH('Player Compare Data'!C$36,'RL Data'!$B$5:$S$5,0),FALSE) -> 3699.43 | U38: =$W$2 -> CLRTY | V38: =SUMIFS('RL Data'!M6:M18,'RL Data'!C6:C18,'Player Compare Data'!U38)/COUNTIF('RL Data'!C6:C18,'Player Compare Data'!U38) -> 3881.825
C39: =(C38-C37)/C37 -> 0.007001097 | V39: =IFERROR((V38-V37)/V37,"One or more Values is 0") -> 0.10284446
C40: =IFERROR(IF(C39<0,CONCATENATE(B38," Had ",TEXT(C39*-1,"0.00%")," Less Avg Teammate Disatance Compared To ",B37),CONCATENATE(B38," Had ",TEXT(C39,"0.00%")," More Avg Teammate Disatance Compared To ",B37)),"One Or More Data Values is 0") -> Squishy Had 0.70% More Avg Teammate Disatance Compared To GarrettG | V40: =IFERROR(IF(V39<0,CONCATENATE(U38," Had ",TEXT(V39*-1,"0.00%")," Less Avg Teammate Disatance Compared To ",U37),CONCATENATE(U38," Had ",TEXT(V39,"0.00%")," More Avg Teammate Disatance Compared To ",U37)),"One Or More Data Values is 0") -> CLRTY Had 10.28% More Avg Teammate Disatance Compared To AEY
C43: BCPM Percentile | D43: BPM Percentile
A44: BCPM Percentile | B44: =$C$2 -> GarrettG | C44: =VLOOKUP($B44,'RL Data'!$B$5:$S$18,MATCH('Player Compare Data'!C$43,'RL Data'!$B$5:$S$5,0),FALSE) -> 0.2 | D44: =1-C44 -> 0.8
A45: BCPM Percentile | B45: =$D$2 -> Squishy | C45: =VLOOKUP($B45,'RL Data'!$B$5:$S$18,MATCH('Player Compare Data'!C$43,'RL Data'!$B$5:$S$5,0),FALSE) -> 0.4 | D45: =1-C45 -> 0.6
A46: BPM Percentile | B46: =$C$2 -> GarrettG | C46: =VLOOKUP($B44,'RL Data'!$B$5:$S$18,MATCH('Player Compare Data'!D$43,'RL Data'!$B$5:$S$5,0),FALSE) -> 0.2 | D46: =1-C46 -> 0.8
A47: BPM Percentile | B47: =$D$2 -> Squishy | C47: =VLOOKUP($B45,'RL Data'!$B$5:$S$18,MATCH('Player Compare Data'!D$43,'RL Data'!$B$5:$S$5,0),FALSE) -> 0.6 | D47: =1-C47 -> 0.4
D78: BCPM Value
D79: BCPM Percentile
D80: BPM
...

Sheet Algo Framework
B3: Rules
B4: More Small Pad, Less Big Pad - midfield control
